2020-10-05 20:21:18,502 INFO: Microblog startup [in /Users/juan/Development/Projects/Python/Python_Web_Development/app/__init__.py:50]
2020-10-05 20:21:55,593 ERROR: Exception on /edit_profile [POST] [in /Users/juan/Development/Projects/Python/Python_Web_Development/venv/lib/python3.8/site-packages/flask/app.py:1891]
Traceback (most recent call last):
  File "/Users/juan/Development/Projects/Python/Python_Web_Development/venv/lib/python3.8/site-packages/sqlalchemy/engine/base.py", line 1276, in _execute_context
    self.dialect.do_execute(
  File "/Users/juan/Development/Projects/Python/Python_Web_Development/venv/lib/python3.8/site-packages/sqlalchemy/engine/default.py", line 593, in do_execute
    cursor.execute(statement, parameters)
sqlite3.IntegrityError: UNIQUE constraint failed: user.username

The above exception was the direct cause of the following exception:

Traceback (most recent call last):
  File "/Users/juan/Development/Projects/Python/Python_Web_Development/venv/lib/python3.8/site-packages/flask/app.py", line 2447, in wsgi_app
    response = self.full_dispatch_request()
  File "/Users/juan/Development/Projects/Python/Python_Web_Development/venv/lib/python3.8/site-packages/flask/app.py", line 1952, in full_dispatch_request
    rv = self.handle_user_exception(e)
  File "/Users/juan/Development/Projects/Python/Python_Web_Development/venv/lib/python3.8/site-packages/flask/app.py", line 1821, in handle_user_exception
    reraise(exc_type, exc_value, tb)
  File "/Users/juan/Development/Projects/Python/Python_Web_Development/venv/lib/python3.8/site-packages/flask/_compat.py", line 39, in reraise
    raise value
  File "/Users/juan/Development/Projects/Python/Python_Web_Development/venv/lib/python3.8/site-packages/flask/app.py", line 1950, in full_dispatch_request
    rv = self.dispatch_request()
  File "/Users/juan/Development/Projects/Python/Python_Web_Development/venv/lib/python3.8/site-packages/flask/app.py", line 1936, in dispatch_request
    return self.view_functions[rule.endpoint](**req.view_args)
  File "/Users/juan/Development/Projects/Python/Python_Web_Development/venv/lib/python3.8/site-packages/flask_login/utils.py", line 272, in decorated_view
    return func(*args, **kwargs)
  File "/Users/juan/Development/Projects/Python/Python_Web_Development/app/routes.py", line 85, in edit_profile
    db.session.commit()
  File "/Users/juan/Development/Projects/Python/Python_Web_Development/venv/lib/python3.8/site-packages/sqlalchemy/orm/scoping.py", line 163, in do
    return getattr(self.registry(), name)(*args, **kwargs)
  File "/Users/juan/Development/Projects/Python/Python_Web_Development/venv/lib/python3.8/site-packages/sqlalchemy/orm/session.py", line 1042, in commit
    self.transaction.commit()
  File "/Users/juan/Development/Projects/Python/Python_Web_Development/venv/lib/python3.8/site-packages/sqlalchemy/orm/session.py", line 504, in commit
    self._prepare_impl()
  File "/Users/juan/Development/Projects/Python/Python_Web_Development/venv/lib/python3.8/site-packages/sqlalchemy/orm/session.py", line 483, in _prepare_impl
    self.session.flush()
  File "/Users/juan/Development/Projects/Python/Python_Web_Development/venv/lib/python3.8/site-packages/sqlalchemy/orm/session.py", line 2523, in flush
    self._flush(objects)
  File "/Users/juan/Development/Projects/Python/Python_Web_Development/venv/lib/python3.8/site-packages/sqlalchemy/orm/session.py", line 2664, in _flush
    transaction.rollback(_capture_exception=True)
  File "/Users/juan/Development/Projects/Python/Python_Web_Development/venv/lib/python3.8/site-packages/sqlalchemy/util/langhelpers.py", line 68, in __exit__
    compat.raise_(
  File "/Users/juan/Development/Projects/Python/Python_Web_Development/venv/lib/python3.8/site-packages/sqlalchemy/util/compat.py", line 182, in raise_
    raise exception
  File "/Users/juan/Development/Projects/Python/Python_Web_Development/venv/lib/python3.8/site-packages/sqlalchemy/orm/session.py", line 2624, in _flush
    flush_context.execute()
  File "/Users/juan/Development/Projects/Python/Python_Web_Development/venv/lib/python3.8/site-packages/sqlalchemy/orm/unitofwork.py", line 422, in execute
    rec.execute(self)
  File "/Users/juan/Development/Projects/Python/Python_Web_Development/venv/lib/python3.8/site-packages/sqlalchemy/orm/unitofwork.py", line 586, in execute
    persistence.save_obj(
  File "/Users/juan/Development/Projects/Python/Python_Web_Development/venv/lib/python3.8/site-packages/sqlalchemy/orm/persistence.py", line 230, in save_obj
    _emit_update_statements(
  File "/Users/juan/Development/Projects/Python/Python_Web_Development/venv/lib/python3.8/site-packages/sqlalchemy/orm/persistence.py", line 994, in _emit_update_statements
    c = cached_connections[connection].execute(
  File "/Users/juan/Development/Projects/Python/Python_Web_Development/venv/lib/python3.8/site-packages/sqlalchemy/engine/base.py", line 1011, in execute
    return meth(self, multiparams, params)
  File "/Users/juan/Development/Projects/Python/Python_Web_Development/venv/lib/python3.8/site-packages/sqlalchemy/sql/elements.py", line 298, in _execute_on_connection
    return connection._execute_clauseelement(self, multiparams, params)
  File "/Users/juan/Development/Projects/Python/Python_Web_Development/venv/lib/python3.8/site-packages/sqlalchemy/engine/base.py", line 1124, in _execute_clauseelement
    ret = self._execute_context(
  File "/Users/juan/Development/Projects/Python/Python_Web_Development/venv/lib/python3.8/site-packages/sqlalchemy/engine/base.py", line 1316, in _execute_context
    self._handle_dbapi_exception(
  File "/Users/juan/Development/Projects/Python/Python_Web_Development/venv/lib/python3.8/site-packages/sqlalchemy/engine/base.py", line 1510, in _handle_dbapi_exception
    util.raise_(
  File "/Users/juan/Development/Projects/Python/Python_Web_Development/venv/lib/python3.8/site-packages/sqlalchemy/util/compat.py", line 182, in raise_
    raise exception
  File "/Users/juan/Development/Projects/Python/Python_Web_Development/venv/lib/python3.8/site-packages/sqlalchemy/engine/base.py", line 1276, in _execute_context
    self.dialect.do_execute(
  File "/Users/juan/Development/Projects/Python/Python_Web_Development/venv/lib/python3.8/site-packages/sqlalchemy/engine/default.py", line 593, in do_execute
    cursor.execute(statement, parameters)
sqlalchemy.exc.IntegrityError: (sqlite3.IntegrityError) UNIQUE constraint failed: user.username
[SQL: UPDATE user SET username=?, about_me=? WHERE user.id = ?]
[parameters: ('susan', "Hi, I'm Juan", 1)]
(Background on this error at: http://sqlalche.me/e/13/gkpj)
2020-10-05 20:30:46,583 INFO: Microblog startup [in /Users/juan/Development/Projects/Python/Python_Web_Development/app/__init__.py:50]
2020-10-16 18:32:36,703 INFO: Microblog startup [in /Users/juan/Development/Projects/Python/Python_Web_Development/app/__init__.py:50]
2020-10-16 18:32:55,290 INFO: Microblog startup [in /Users/juan/Development/Projects/Python/Python_Web_Development/app/__init__.py:50]
2020-10-16 18:48:34,340 INFO: Microblog startup [in /Users/juan/Development/Projects/Python/Python_Web_Development/app/__init__.py:50]
2020-10-16 19:10:20,006 INFO: Microblog startup [in /Users/juan/Development/Projects/Python/Python_Web_Development/app/__init__.py:50]
2020-10-16 19:51:43,819 INFO: Microblog startup [in /Users/juan/Development/Projects/Python/Python_Web_Development/app/__init__.py:50]
2020-10-16 19:54:15,936 INFO: Microblog startup [in /Users/juan/Development/Projects/Python/Python_Web_Development/app/__init__.py:50]
2020-10-16 20:15:24,686 INFO: Microblog startup [in /Users/juan/Development/Projects/Python/Python_Web_Development/app/__init__.py:50]
2020-10-16 20:15:49,922 ERROR: Exception on /favicon.ico [GET] [in /Users/juan/Development/Projects/Python/Python_Web_Development/venv/lib/python3.8/site-packages/flask/app.py:1891]
Traceback (most recent call last):
  File "/Users/juan/Development/Projects/Python/Python_Web_Development/venv/lib/python3.8/site-packages/flask/app.py", line 1950, in full_dispatch_request
    rv = self.dispatch_request()
  File "/Users/juan/Development/Projects/Python/Python_Web_Development/venv/lib/python3.8/site-packages/flask/app.py", line 1926, in dispatch_request
    self.raise_routing_exception(req)
  File "/Users/juan/Development/Projects/Python/Python_Web_Development/venv/lib/python3.8/site-packages/flask/app.py", line 1908, in raise_routing_exception
    raise request.routing_exception
  File "/Users/juan/Development/Projects/Python/Python_Web_Development/venv/lib/python3.8/site-packages/flask/ctx.py", line 350, in match_request
    result = self.url_adapter.match(return_rule=True)
  File "/Users/juan/Development/Projects/Python/Python_Web_Development/venv/lib/python3.8/site-packages/werkzeug/routing.py", line 1945, in match
    raise NotFound()
werkzeug.exceptions.NotFound: 404 Not Found: The requested URL was not found on the server. If you entered the URL manually please check your spelling and try again.

During handling of the above exception, another exception occurred:

Traceback (most recent call last):
  File "/Users/juan/Development/Projects/Python/Python_Web_Development/venv/lib/python3.8/site-packages/flask/app.py", line 2447, in wsgi_app
    response = self.full_dispatch_request()
  File "/Users/juan/Development/Projects/Python/Python_Web_Development/venv/lib/python3.8/site-packages/flask/app.py", line 1952, in full_dispatch_request
    rv = self.handle_user_exception(e)
  File "/Users/juan/Development/Projects/Python/Python_Web_Development/venv/lib/python3.8/site-packages/flask/app.py", line 1816, in handle_user_exception
    return self.handle_http_exception(e)
  File "/Users/juan/Development/Projects/Python/Python_Web_Development/venv/lib/python3.8/site-packages/flask/app.py", line 1744, in handle_http_exception
    return handler(e)
TypeError: not_found() takes 0 positional arguments but 1 was given
